<robot name = "robot">
    <link name="spine0">
        <inertial>
            <origin xyz="0 0 1" rpy="0 0 0"/>
            <mass value="1" />
            <inertia ixx="100" ixy="0" ixz="0" iyy="100" iyz="0" izz="100" />
        </inertial>
        <visual>
            <origin xyz="0 0 1" rpy="0 0 0"/>
            <geometry>
                <box size="0.43273769419922903 0.4703553226787157 0.33275814255819236" />
            </geometry>
            <material name="Cyan">
                <color rgba="0 1.0 1.0 1.0"/>
            </material>
        </visual>
        <collision>
            <origin xyz="0 0 1" rpy="0 0 0"/>
            <geometry>
                <box size="0.43273769419922903 0.4703553226787157 0.33275814255819236" />
            </geometry>
        </collision>
    </link>
    <joint name="spine0_arm0" type="revolute">
       <parent link="spine0"/>
       <child  link="arm0"/>
       <origin rpy="0 0 0" xyz="0.0 0.23517766133935786 1.0" />
     <axis xyz="0 1 0"/>
       <limit effort="0.0" lower="-3.14159" upper="3.14159" velocity="0.0"/>
    </joint>
    <link name="arm0">
        <inertial>
            <origin xyz="0.0 0.18734397408131293 0.0" rpy="0 0 0"/>
            <mass value="1" />
            <inertia ixx="100" ixy="0" ixz="0" iyy="100" iyz="0" izz="100" />
        </inertial>
        <visual>
            <origin xyz="0.0 0.18734397408131293 0.0" rpy="0 0 0"/>
            <geometry>
                <box size="0.28104053186655087 0.37468794816262585 0.2683559904535957" />
            </geometry>
            <material name="Cyan">
                <color rgba="0 1.0 1.0 1.0"/>
            </material>
        </visual>
        <collision>
            <origin xyz="0.0 0.18734397408131293 0.0" rpy="0 0 0"/>
            <geometry>
                <box size="0.28104053186655087 0.37468794816262585 0.2683559904535957" />
            </geometry>
        </collision>
    </link>
    <joint name="arm0_leg0" type="revolute">
       <parent link="arm0"/>
       <child  link="leg0"/>
       <origin rpy="0 0 0" xyz="0.0 0.37468794816262585 0.0" />
     <axis xyz="0 1 0"/>
       <limit effort="0.0" lower="-3.14159" upper="3.14159" velocity="0.0"/>
    </joint>
    <link name="leg0">
        <inertial>
            <origin xyz="0.0 0.0 0.11016289439275517" rpy="0 0 0"/>
            <mass value="1" />
            <inertia ixx="100" ixy="0" ixz="0" iyy="100" iyz="0" izz="100" />
        </inertial>
        <visual>
            <origin xyz="0.0 0.0 0.11016289439275517" rpy="0 0 0"/>
            <geometry>
                <box size="0.21078039889991315 0.28101596112196936 0.22032578878551035" />
            </geometry>
            <material name="Cyan">
                <color rgba="0 1.0 1.0 1.0"/>
            </material>
        </visual>
        <collision>
            <origin xyz="0.0 0.0 0.11016289439275517" rpy="0 0 0"/>
            <geometry>
                <box size="0.21078039889991315 0.28101596112196936 0.22032578878551035" />
            </geometry>
        </collision>
    </link>
    <joint name="spine0_spine1" type="revolute">
       <parent link="spine0"/>
       <child  link="spine1"/>
       <origin rpy="0 0 0" xyz="-0.21636884709961451 0.0 1.0" />
     <axis xyz="0 1 0"/>
       <limit effort="0.0" lower="-3.14159" upper="3.14159" velocity="0.0"/>
    </joint>
    <link name="spine1">
        <inertial>
            <origin xyz="-0.2569939401587393 0.0 0.0" rpy="0 0 0"/>
            <mass value="1" />
            <inertia ixx="100" ixy="0" ixz="0" iyy="100" iyz="0" izz="100" />
        </inertial>
        <visual>
            <origin xyz="-0.2569939401587393 0.0 0.0" rpy="0 0 0"/>
            <geometry>
                <box size="0.5139878803174786 0.35678871716831406 0.6651466225830087" />
            </geometry>
            <material name="Cyan">
                <color rgba="0 1.0 1.0 1.0"/>
            </material>
        </visual>
        <collision>
            <origin xyz="-0.2569939401587393 0.0 0.0" rpy="0 0 0"/>
            <geometry>
                <box size="0.5139878803174786 0.35678871716831406 0.6651466225830087" />
            </geometry>
        </collision>
    </link>
</robot>