<robot name = "robot">
    <link name="Body0">
        <inertial>
            <origin xyz="2.0 0.0 0.5" rpy="0 0 0"/>
            <mass value="1" />
            <inertia ixx="100" ixy="0" ixz="0" iyy="100" iyz="0" izz="100" />
        </inertial>
        <visual>
            <origin xyz="2.0 0.0 0.5" rpy="0 0 0"/>
            <geometry>
                <box size="1.7174171325425494 1.8074058492705711 0.6554370983193305" />
            </geometry>
            <material name="Blue">
                <color rgba="0 0.0 1.0 1.0"/>
            </material>
        </visual>
        <collision>
            <origin xyz="2.0 0.0 0.5" rpy="0 0 0"/>
            <geometry>
                <box size="1.7174171325425494 1.8074058492705711 0.6554370983193305" />
            </geometry>
        </collision>
    </link>
    <joint name="Body0_Body1" type="revolute">
       <parent link="Body0"/>
       <child  link="Body1"/>
       <origin rpy="0 0 0" xyz="1.1412914337287252 0.0 0.5" />
     <axis xyz="0 1 0"/>
       <limit effort="0.0" lower="-3.14159" upper="3.14159" velocity="0.0"/>
    </joint>
    <link name="Body1">
        <inertial>
            <origin xyz="-1.2624468724180735 0.0 0.0" rpy="0 0 0"/>
            <mass value="1" />
            <inertia ixx="100" ixy="0" ixz="0" iyy="100" iyz="0" izz="100" />
        </inertial>
        <visual>
            <origin xyz="-1.2624468724180735 0.0 0.0" rpy="0 0 0"/>
            <geometry>
                <box size="2.524893744836147 1.0277036109938238 0.8534568903573734" />
            </geometry>
            <material name="Blue">
                <color rgba="0 0.0 1.0 1.0"/>
            </material>
        </visual>
        <collision>
            <origin xyz="-1.2624468724180735 0.0 0.0" rpy="0 0 0"/>
            <geometry>
                <box size="2.524893744836147 1.0277036109938238 0.8534568903573734" />
            </geometry>
        </collision>
    </link>
    <joint name="Body1_Body2" type="revolute">
       <parent link="Body1"/>
       <child  link="Body2"/>
       <origin rpy="0 0 0" xyz="-1.2624468724180735 -0.5138518054969119 0.0" />
     <axis xyz="0 1 0"/>
       <limit effort="0.0" lower="-3.14159" upper="3.14159" velocity="0.0"/>
    </joint>
    <link name="Body2">
        <inertial>
            <origin xyz="0.0 -0.7114979117600088 0.0" rpy="0 0 0"/>
            <mass value="1" />
            <inertia ixx="100" ixy="0" ixz="0" iyy="100" iyz="0" izz="100" />
        </inertial>
        <visual>
            <origin xyz="0.0 -0.7114979117600088 0.0" rpy="0 0 0"/>
            <geometry>
                <box size="0.6906735418387882 1.4229958235200175 0.548323162845989" />
            </geometry>
            <material name="Green">
                <color rgba="0 1.0 0.0 1.0"/>
            </material>
        </visual>
        <collision>
            <origin xyz="0.0 -0.7114979117600088 0.0" rpy="0 0 0"/>
            <geometry>
                <box size="0.6906735418387882 1.4229958235200175 0.548323162845989" />
            </geometry>
        </collision>
    </link>
    <joint name="Body2_Body3" type="revolute">
       <parent link="Body2"/>
       <child  link="Body3"/>
       <origin rpy="0 0 0" xyz="0.0 -1.4229958235200175 0.0" />
     <axis xyz="0 0 1"/>
       <limit effort="0.0" lower="-3.14159" upper="3.14159" velocity="0.0"/>
    </joint>
    <link name="Body3">
        <inertial>
            <origin xyz="0.0 0.0 -0.25" rpy="0 0 0"/>
            <mass value="1" />
            <inertia ixx="100" ixy="0" ixz="0" iyy="100" iyz="0" izz="100" />
        </inertial>
        <visual>
            <origin xyz="0.0 0.0 -0.25" rpy="0 0 0"/>
            <geometry>
                <box size="0.6906735418387882 0.7114979117600088 0.5" />
            </geometry>
            <material name="Blue">
                <color rgba="0 0.0 1.0 1.0"/>
            </material>
        </visual>
        <collision>
            <origin xyz="0.0 0.0 -0.25" rpy="0 0 0"/>
            <geometry>
                <box size="0.6906735418387882 0.7114979117600088 0.5" />
            </geometry>
        </collision>
    </link>
    <joint name="Body3_Body4" type="revolute">
       <parent link="Body3"/>
       <child  link="Body4"/>
       <origin rpy="0 0 0" xyz="0.0 2.450699434513841 0.0" />
     <axis xyz="0 0 1"/>
       <limit effort="0.0" lower="-3.14159" upper="3.14159" velocity="0.0"/>
    </joint>
    <link name="Body4">
        <inertial>
            <origin xyz="0.0 0.4632661139153583 0.0" rpy="0 0 0"/>
            <mass value="1" />
            <inertia ixx="100" ixy="0" ixz="0" iyy="100" iyz="0" izz="100" />
        </inertial>
        <visual>
            <origin xyz="0.0 0.4632661139153583 0.0" rpy="0 0 0"/>
            <geometry>
                <box size="0.5993256404398629 0.9265322278307166 0.6602251018801432" />
            </geometry>
            <material name="Blue">
                <color rgba="0 0.0 1.0 1.0"/>
            </material>
        </visual>
        <collision>
            <origin xyz="0.0 0.4632661139153583 0.0" rpy="0 0 0"/>
            <geometry>
                <box size="0.5993256404398629 0.9265322278307166 0.6602251018801432" />
            </geometry>
        </collision>
    </link>
    <joint name="Body4_Body5" type="revolute">
       <parent link="Body4"/>
       <child  link="Body5"/>
       <origin rpy="0 0 0" xyz="0.0 0.9265322278307166 0.0" />
     <axis xyz="0 0 1"/>
       <limit effort="0.0" lower="-3.14159" upper="3.14159" velocity="0.0"/>
    </joint>
    <link name="Body5">
        <inertial>
            <origin xyz="0.0 0.0 -0.25" rpy="0 0 0"/>
            <mass value="1" />
            <inertia ixx="100" ixy="0" ixz="0" iyy="100" iyz="0" izz="100" />
        </inertial>
        <visual>
            <origin xyz="0.0 0.0 -0.25" rpy="0 0 0"/>
            <geometry>
                <box size="0.5993256404398629 0.4632661139153583 0.5" />
            </geometry>
            <material name="Blue">
                <color rgba="0 0.0 1.0 1.0"/>
            </material>
        </visual>
        <collision>
            <origin xyz="0.0 0.0 -0.25" rpy="0 0 0"/>
            <geometry>
                <box size="0.5993256404398629 0.4632661139153583 0.5" />
            </geometry>
        </collision>
    </link>
    <joint name="Body5_Body6" type="revolute">
       <parent link="Body5"/>
       <child  link="Body6"/>
       <origin rpy="0 0 0" xyz="-1.2624468724180735 -1.4403840333276285 0.0" />
     <axis xyz="0 1 0"/>
       <limit effort="0.0" lower="-3.14159" upper="3.14159" velocity="0.0"/>
    </joint>
    <link name="Body6">
        <inertial>
            <origin xyz="-0.782261436232961 0.0 0.0" rpy="0 0 0"/>
            <mass value="1" />
            <inertia ixx="100" ixy="0" ixz="0" iyy="100" iyz="0" izz="100" />
        </inertial>
        <visual>
            <origin xyz="-0.782261436232961 0.0 0.0" rpy="0 0 0"/>
            <geometry>
                <box size="1.564522872465922 1.2903780506464622 0.04201168758982954" />
            </geometry>
            <material name="Blue">
                <color rgba="0 0.0 1.0 1.0"/>
            </material>
        </visual>
        <collision>
            <origin xyz="-0.782261436232961 0.0 0.0" rpy="0 0 0"/>
            <geometry>
                <box size="1.564522872465922 1.2903780506464622 0.04201168758982954" />
            </geometry>
        </collision>
    </link>
    <joint name="Body6_Body7" type="revolute">
       <parent link="Body6"/>
       <child  link="Body7"/>
       <origin rpy="0 0 0" xyz="-0.782261436232961 -0.6451890253232311 0.0" />
     <axis xyz="0 1 0"/>
       <limit effort="0.0" lower="-3.14159" upper="3.14159" velocity="0.0"/>
    </joint>
    <link name="Body7">
        <inertial>
            <origin xyz="0.0 -0.20342366655793986 0.0" rpy="0 0 0"/>
            <mass value="1" />
            <inertia ixx="100" ixy="0" ixz="0" iyy="100" iyz="0" izz="100" />
        </inertial>
        <visual>
            <origin xyz="0.0 -0.20342366655793986 0.0" rpy="0 0 0"/>
            <geometry>
                <box size="0.14413370264367875 0.40684733311587973 0.0348181483489102" />
            </geometry>
            <material name="Blue">
                <color rgba="0 0.0 1.0 1.0"/>
            </material>
        </visual>
        <collision>
            <origin xyz="0.0 -0.20342366655793986 0.0" rpy="0 0 0"/>
            <geometry>
                <box size="0.14413370264367875 0.40684733311587973 0.0348181483489102" />
            </geometry>
        </collision>
    </link>
    <joint name="Body7_Body8" type="revolute">
       <parent link="Body7"/>
       <child  link="Body8"/>
       <origin rpy="0 0 0" xyz="0.0 -0.40684733311587973 0.0" />
     <axis xyz="0 0 1"/>
       <limit effort="0.0" lower="-3.14159" upper="3.14159" velocity="0.0"/>
    </joint>
    <link name="Body8">
        <inertial>
            <origin xyz="0.0 0.0 -0.25" rpy="0 0 0"/>
            <mass value="1" />
            <inertia ixx="100" ixy="0" ixz="0" iyy="100" iyz="0" izz="100" />
        </inertial>
        <visual>
            <origin xyz="0.0 0.0 -0.25" rpy="0 0 0"/>
            <geometry>
                <box size="0.14413370264367875 0.20342366655793986 0.5" />
            </geometry>
            <material name="Blue">
                <color rgba="0 0.0 1.0 1.0"/>
            </material>
        </visual>
        <collision>
            <origin xyz="0.0 0.0 -0.25" rpy="0 0 0"/>
            <geometry>
                <box size="0.14413370264367875 0.20342366655793986 0.5" />
            </geometry>
        </collision>
    </link>
    <joint name="Body8_Body9" type="revolute">
       <parent link="Body8"/>
       <child  link="Body9"/>
       <origin rpy="0 0 0" xyz="0.0 1.6972253837623419 0.0" />
     <axis xyz="0 0 1"/>
       <limit effort="0.0" lower="-3.14159" upper="3.14159" velocity="0.0"/>
    </joint>
    <link name="Body9">
        <inertial>
            <origin xyz="0.0 0.6358130745615919 0.0" rpy="0 0 0"/>
            <mass value="1" />
            <inertia ixx="100" ixy="0" ixz="0" iyy="100" iyz="0" izz="100" />
        </inertial>
        <visual>
            <origin xyz="0.0 0.6358130745615919 0.0" rpy="0 0 0"/>
            <geometry>
                <box size="0.6692248971421628 1.2716261491231837 0.023969191809200985" />
            </geometry>
            <material name="Green">
                <color rgba="0 1.0 0.0 1.0"/>
            </material>
        </visual>
        <collision>
            <origin xyz="0.0 0.6358130745615919 0.0" rpy="0 0 0"/>
            <geometry>
                <box size="0.6692248971421628 1.2716261491231837 0.023969191809200985" />
            </geometry>
        </collision>
    </link>
    <joint name="Body9_Body10" type="revolute">
       <parent link="Body9"/>
       <child  link="Body10"/>
       <origin rpy="0 0 0" xyz="0.0 1.2716261491231837 0.0" />
     <axis xyz="0 0 1"/>
       <limit effort="0.0" lower="-3.14159" upper="3.14159" velocity="0.0"/>
    </joint>
    <link name="Body10">
        <inertial>
            <origin xyz="0.0 0.0 -0.25" rpy="0 0 0"/>
            <mass value="1" />
            <inertia ixx="100" ixy="0" ixz="0" iyy="100" iyz="0" izz="100" />
        </inertial>
        <visual>
            <origin xyz="0.0 0.0 -0.25" rpy="0 0 0"/>
            <geometry>
                <box size="0.6692248971421628 0.6358130745615919 0.5" />
            </geometry>
            <material name="Blue">
                <color rgba="0 0.0 1.0 1.0"/>
            </material>
        </visual>
        <collision>
            <origin xyz="0.0 0.0 -0.25" rpy="0 0 0"/>
            <geometry>
                <box size="0.6692248971421628 0.6358130745615919 0.5" />
            </geometry>
        </collision>
    </link>
    <joint name="Body10_Body11" type="revolute">
       <parent link="Body10"/>
       <child  link="Body11"/>
       <origin rpy="0 0 0" xyz="-0.782261436232961 -1.9168151744464148 0.0" />
     <axis xyz="0 1 0"/>
       <limit effort="0.0" lower="-3.14159" upper="3.14159" velocity="0.0"/>
    </joint>
    <link name="Body11">
        <inertial>
            <origin xyz="-0.32014689321772144 0.0 0.0" rpy="0 0 0"/>
            <mass value="1" />
            <inertia ixx="100" ixy="0" ixz="0" iyy="100" iyz="0" izz="100" />
        </inertial>
        <visual>
            <origin xyz="-0.32014689321772144 0.0 0.0" rpy="0 0 0"/>
            <geometry>
                <box size="0.6402937864354429 0.13280849908005443 0.39055173399402443" />
            </geometry>
            <material name="Blue">
                <color rgba="0 0.0 1.0 1.0"/>
            </material>
        </visual>
        <collision>
            <origin xyz="-0.32014689321772144 0.0 0.0" rpy="0 0 0"/>
            <geometry>
                <box size="0.6402937864354429 0.13280849908005443 0.39055173399402443" />
            </geometry>
        </collision>
    </link>
    <joint name="Body11_Body12" type="revolute">
       <parent link="Body11"/>
       <child  link="Body12"/>
       <origin rpy="0 0 0" xyz="-0.32014689321772144 -0.06640424954002722 0.0" />
     <axis xyz="0 1 0"/>
       <limit effort="0.0" lower="-3.14159" upper="3.14159" velocity="0.0"/>
    </joint>
    <link name="Body12">
        <inertial>
            <origin xyz="0.0 -0.9156132591843545 0.0" rpy="0 0 0"/>
            <mass value="1" />
            <inertia ixx="100" ixy="0" ixz="0" iyy="100" iyz="0" izz="100" />
        </inertial>
        <visual>
            <origin xyz="0.0 -0.9156132591843545 0.0" rpy="0 0 0"/>
            <geometry>
                <box size="0.12966644772125094 1.831226518368709 0.3353641025668043" />
            </geometry>
            <material name="Blue">
                <color rgba="0 0.0 1.0 1.0"/>
            </material>
        </visual>
        <collision>
            <origin xyz="0.0 -0.9156132591843545 0.0" rpy="0 0 0"/>
            <geometry>
                <box size="0.12966644772125094 1.831226518368709 0.3353641025668043" />
            </geometry>
        </collision>
    </link>
    <joint name="Body12_Body13" type="revolute">
       <parent link="Body12"/>
       <child  link="Body13"/>
       <origin rpy="0 0 0" xyz="0.0 -1.831226518368709 0.0" />
     <axis xyz="0 0 1"/>
       <limit effort="0.0" lower="-3.14159" upper="3.14159" velocity="0.0"/>
    </joint>
    <link name="Body13">
        <inertial>
            <origin xyz="0.0 0.0 -0.25" rpy="0 0 0"/>
            <mass value="1" />
            <inertia ixx="100" ixy="0" ixz="0" iyy="100" iyz="0" izz="100" />
        </inertial>
        <visual>
            <origin xyz="0.0 0.0 -0.25" rpy="0 0 0"/>
            <geometry>
                <box size="0.12966644772125094 0.9156132591843545 0.5" />
            </geometry>
            <material name="Blue">
                <color rgba="0 0.0 1.0 1.0"/>
            </material>
        </visual>
        <collision>
            <origin xyz="0.0 0.0 -0.25" rpy="0 0 0"/>
            <geometry>
                <box size="0.12966644772125094 0.9156132591843545 0.5" />
            </geometry>
        </collision>
    </link>
    <joint name="Body13_Body14" type="revolute">
       <parent link="Body13"/>
       <child  link="Body14"/>
       <origin rpy="0 0 0" xyz="0.0 1.9640350174487635 0.0" />
     <axis xyz="0 0 1"/>
       <limit effort="0.0" lower="-3.14159" upper="3.14159" velocity="0.0"/>
    </joint>
    <link name="Body14">
        <inertial>
            <origin xyz="0.0 0.3574005716694124 0.0" rpy="0 0 0"/>
            <mass value="1" />
            <inertia ixx="100" ixy="0" ixz="0" iyy="100" iyz="0" izz="100" />
        </inertial>
        <visual>
            <origin xyz="0.0 0.3574005716694124 0.0" rpy="0 0 0"/>
            <geometry>
                <box size="0.026729639242211358 0.7148011433388248 0.029807890880375363" />
            </geometry>
            <material name="Green">
                <color rgba="0 1.0 0.0 1.0"/>
            </material>
        </visual>
        <collision>
            <origin xyz="0.0 0.3574005716694124 0.0" rpy="0 0 0"/>
            <geometry>
                <box size="0.026729639242211358 0.7148011433388248 0.029807890880375363" />
            </geometry>
        </collision>
    </link>
    <joint name="Body14_Body15" type="revolute">
       <parent link="Body14"/>
       <child  link="Body15"/>
       <origin rpy="0 0 0" xyz="0.0 0.7148011433388248 0.0" />
     <axis xyz="0 0 1"/>
       <limit effort="0.0" lower="-3.14159" upper="3.14159" velocity="0.0"/>
    </joint>
    <link name="Body15">
        <inertial>
            <origin xyz="0.0 0.0 -0.25" rpy="0 0 0"/>
            <mass value="1" />
            <inertia ixx="100" ixy="0" ixz="0" iyy="100" iyz="0" izz="100" />
        </inertial>
        <visual>
            <origin xyz="0.0 0.0 -0.25" rpy="0 0 0"/>
            <geometry>
                <box size="0.026729639242211358 0.3574005716694124 0.5" />
            </geometry>
            <material name="Blue">
                <color rgba="0 0.0 1.0 1.0"/>
            </material>
        </visual>
        <collision>
            <origin xyz="0.0 0.0 -0.25" rpy="0 0 0"/>
            <geometry>
                <box size="0.026729639242211358 0.3574005716694124 0.5" />
            </geometry>
        </collision>
    </link>
    <joint name="Body15_Body16" type="revolute">
       <parent link="Body15"/>
       <child  link="Body16"/>
       <origin rpy="0 0 0" xyz="-0.32014689321772144 -0.781205392878852 0.0" />
     <axis xyz="0 1 0"/>
       <limit effort="0.0" lower="-3.14159" upper="3.14159" velocity="0.0"/>
    </joint>
    <link name="Body16">
        <inertial>
            <origin xyz="-1.3023319854961888 0.0 0.0" rpy="0 0 0"/>
            <mass value="1" />
            <inertia ixx="100" ixy="0" ixz="0" iyy="100" iyz="0" izz="100" />
        </inertial>
        <visual>
            <origin xyz="-1.3023319854961888 0.0 0.0" rpy="0 0 0"/>
            <geometry>
                <box size="2.6046639709923776 0.567880848001838 0.8338234509017347" />
            </geometry>
            <material name="Green">
                <color rgba="0 1.0 0.0 1.0"/>
            </material>
        </visual>
        <collision>
            <origin xyz="-1.3023319854961888 0.0 0.0" rpy="0 0 0"/>
            <geometry>
                <box size="2.6046639709923776 0.567880848001838 0.8338234509017347" />
            </geometry>
        </collision>
    </link>
    <joint name="Body16_Body17" type="revolute">
       <parent link="Body16"/>
       <child  link="Body17"/>
       <origin rpy="0 0 0" xyz="-1.3023319854961888 -0.283940424000919 0.0" />
     <axis xyz="0 1 0"/>
       <limit effort="0.0" lower="-3.14159" upper="3.14159" velocity="0.0"/>
    </joint>
    <link name="Body17">
        <inertial>
            <origin xyz="0.0 -0.2278731366556238 0.0" rpy="0 0 0"/>
            <mass value="1" />
            <inertia ixx="100" ixy="0" ixz="0" iyy="100" iyz="0" izz="100" />
        </inertial>
        <visual>
            <origin xyz="0.0 -0.2278731366556238 0.0" rpy="0 0 0"/>
            <geometry>
                <box size="0.15268046395801604 0.4557462733112476 0.8251342268959918" />
            </geometry>
            <material name="Green">
                <color rgba="0 1.0 0.0 1.0"/>
            </material>
        </visual>
        <collision>
            <origin xyz="0.0 -0.2278731366556238 0.0" rpy="0 0 0"/>
            <geometry>
                <box size="0.15268046395801604 0.4557462733112476 0.8251342268959918" />
            </geometry>
        </collision>
    </link>
    <joint name="Body17_Body18" type="revolute">
       <parent link="Body17"/>
       <child  link="Body18"/>
       <origin rpy="0 0 0" xyz="0.0 -0.4557462733112476 0.0" />
     <axis xyz="0 0 1"/>
       <limit effort="0.0" lower="-3.14159" upper="3.14159" velocity="0.0"/>
    </joint>
    <link name="Body18">
        <inertial>
            <origin xyz="0.0 0.0 -0.25" rpy="0 0 0"/>
            <mass value="1" />
            <inertia ixx="100" ixy="0" ixz="0" iyy="100" iyz="0" izz="100" />
        </inertial>
        <visual>
            <origin xyz="0.0 0.0 -0.25" rpy="0 0 0"/>
            <geometry>
                <box size="0.15268046395801604 0.2278731366556238 0.5" />
            </geometry>
            <material name="Blue">
                <color rgba="0 0.0 1.0 1.0"/>
            </material>
        </visual>
        <collision>
            <origin xyz="0.0 0.0 -0.25" rpy="0 0 0"/>
            <geometry>
                <box size="0.15268046395801604 0.2278731366556238 0.5" />
            </geometry>
        </collision>
    </link>
    <joint name="Body18_Body19" type="revolute">
       <parent link="Body18"/>
       <child  link="Body19"/>
       <origin rpy="0 0 0" xyz="0.0 1.0236271213130856 0.0" />
     <axis xyz="0 0 1"/>
       <limit effort="0.0" lower="-3.14159" upper="3.14159" velocity="0.0"/>
    </joint>
    <link name="Body19">
        <inertial>
            <origin xyz="0.0 0.49151598861706225 0.0" rpy="0 0 0"/>
            <mass value="1" />
            <inertia ixx="100" ixy="0" ixz="0" iyy="100" iyz="0" izz="100" />
        </inertial>
        <visual>
            <origin xyz="0.0 0.49151598861706225 0.0" rpy="0 0 0"/>
            <geometry>
                <box size="1.1450066653558264 0.9830319772341245 0.30499014319434475" />
            </geometry>
            <material name="Blue">
                <color rgba="0 0.0 1.0 1.0"/>
            </material>
        </visual>
        <collision>
            <origin xyz="0.0 0.49151598861706225 0.0" rpy="0 0 0"/>
            <geometry>
                <box size="1.1450066653558264 0.9830319772341245 0.30499014319434475" />
            </geometry>
        </collision>
    </link>
    <joint name="Body19_Body20" type="revolute">
       <parent link="Body19"/>
       <child  link="Body20"/>
       <origin rpy="0 0 0" xyz="0.0 0.9830319772341245 0.0" />
     <axis xyz="0 0 1"/>
       <limit effort="0.0" lower="-3.14159" upper="3.14159" velocity="0.0"/>
    </joint>
    <link name="Body20">
        <inertial>
            <origin xyz="0.0 0.0 -0.25" rpy="0 0 0"/>
            <mass value="1" />
            <inertia ixx="100" ixy="0" ixz="0" iyy="100" iyz="0" izz="100" />
        </inertial>
        <visual>
            <origin xyz="0.0 0.0 -0.25" rpy="0 0 0"/>
            <geometry>
                <box size="1.1450066653558264 0.49151598861706225 0.5" />
            </geometry>
            <material name="Blue">
                <color rgba="0 0.0 1.0 1.0"/>
            </material>
        </visual>
        <collision>
            <origin xyz="0.0 0.0 -0.25" rpy="0 0 0"/>
            <geometry>
                <box size="1.1450066653558264 0.49151598861706225 0.5" />
            </geometry>
        </collision>
    </link>
    <joint name="Body20_Body21" type="revolute">
       <parent link="Body20"/>
       <child  link="Body21"/>
       <origin rpy="0 0 0" xyz="-1.3023319854961888 -1.2669724012350434 0.0" />
     <axis xyz="0 1 0"/>
       <limit effort="0.0" lower="-3.14159" upper="3.14159" velocity="0.0"/>
    </joint>
    <link name="Body21">
        <inertial>
            <origin xyz="-0.5668386092233143 0.0 0.0" rpy="0 0 0"/>
            <mass value="1" />
            <inertia ixx="100" ixy="0" ixz="0" iyy="100" iyz="0" izz="100" />
        </inertial>
        <visual>
            <origin xyz="-0.5668386092233143 0.0 0.0" rpy="0 0 0"/>
            <geometry>
                <box size="1.1336772184466286 0.043089211096427604 0.6043399187150553" />
            </geometry>
            <material name="Green">
                <color rgba="0 1.0 0.0 1.0"/>
            </material>
        </visual>
        <collision>
            <origin xyz="-0.5668386092233143 0.0 0.0" rpy="0 0 0"/>
            <geometry>
                <box size="1.1336772184466286 0.043089211096427604 0.6043399187150553" />
            </geometry>
        </collision>
    </link>
    <joint name="Body21_Body22" type="revolute">
       <parent link="Body21"/>
       <child  link="Body22"/>
       <origin rpy="0 0 0" xyz="-0.5668386092233143 -0.021544605548213802 0.0" />
     <axis xyz="0 1 0"/>
       <limit effort="0.0" lower="-3.14159" upper="3.14159" velocity="0.0"/>
    </joint>
    <link name="Body22">
        <inertial>
            <origin xyz="0.0 -0.029980334869270542 0.0" rpy="0 0 0"/>
            <mass value="1" />
            <inertia ixx="100" ixy="0" ixz="0" iyy="100" iyz="0" izz="100" />
        </inertial>
        <visual>
            <origin xyz="0.0 -0.029980334869270542 0.0" rpy="0 0 0"/>
            <geometry>
                <box size="0.15212660837358213 0.059960669738541084 0.5946943453435014" />
            </geometry>
            <material name="Blue">
                <color rgba="0 0.0 1.0 1.0"/>
            </material>
        </visual>
        <collision>
            <origin xyz="0.0 -0.029980334869270542 0.0" rpy="0 0 0"/>
            <geometry>
                <box size="0.15212660837358213 0.059960669738541084 0.5946943453435014" />
            </geometry>
        </collision>
    </link>
    <joint name="Body22_Body23" type="revolute">
       <parent link="Body22"/>
       <child  link="Body23"/>
       <origin rpy="0 0 0" xyz="0.0 -0.059960669738541084 0.0" />
     <axis xyz="0 0 1"/>
       <limit effort="0.0" lower="-3.14159" upper="3.14159" velocity="0.0"/>
    </joint>
    <link name="Body23">
        <inertial>
            <origin xyz="0.0 0.0 -0.25" rpy="0 0 0"/>
            <mass value="1" />
            <inertia ixx="100" ixy="0" ixz="0" iyy="100" iyz="0" izz="100" />
        </inertial>
        <visual>
            <origin xyz="0.0 0.0 -0.25" rpy="0 0 0"/>
            <geometry>
                <box size="0.15212660837358213 0.029980334869270542 0.5" />
            </geometry>
            <material name="Blue">
                <color rgba="0 0.0 1.0 1.0"/>
            </material>
        </visual>
        <collision>
            <origin xyz="0.0 0.0 -0.25" rpy="0 0 0"/>
            <geometry>
                <box size="0.15212660837358213 0.029980334869270542 0.5" />
            </geometry>
        </collision>
    </link>
    <joint name="Body23_Body24" type="revolute">
       <parent link="Body23"/>
       <child  link="Body24"/>
       <origin rpy="0 0 0" xyz="0.0 0.10304988083496869 0.0" />
     <axis xyz="0 0 1"/>
       <limit effort="0.0" lower="-3.14159" upper="3.14159" velocity="0.0"/>
    </joint>
    <link name="Body24">
        <inertial>
            <origin xyz="0.0 0.8322819496741144 0.0" rpy="0 0 0"/>
            <mass value="1" />
            <inertia ixx="100" ixy="0" ixz="0" iyy="100" iyz="0" izz="100" />
        </inertial>
        <visual>
            <origin xyz="0.0 0.8322819496741144 0.0" rpy="0 0 0"/>
            <geometry>
                <box size="0.2697420647060007 1.6645638993482288 0.21669607748892494" />
            </geometry>
            <material name="Blue">
                <color rgba="0 0.0 1.0 1.0"/>
            </material>
        </visual>
        <collision>
            <origin xyz="0.0 0.8322819496741144 0.0" rpy="0 0 0"/>
            <geometry>
                <box size="0.2697420647060007 1.6645638993482288 0.21669607748892494" />
            </geometry>
        </collision>
    </link>
    <joint name="Body24_Body25" type="revolute">
       <parent link="Body24"/>
       <child  link="Body25"/>
       <origin rpy="0 0 0" xyz="0.0 1.6645638993482288 0.0" />
     <axis xyz="0 0 1"/>
       <limit effort="0.0" lower="-3.14159" upper="3.14159" velocity="0.0"/>
    </joint>
    <link name="Body25">
        <inertial>
            <origin xyz="0.0 0.0 -0.25" rpy="0 0 0"/>
            <mass value="1" />
            <inertia ixx="100" ixy="0" ixz="0" iyy="100" iyz="0" izz="100" />
        </inertial>
        <visual>
            <origin xyz="0.0 0.0 -0.25" rpy="0 0 0"/>
            <geometry>
                <box size="0.2697420647060007 0.8322819496741144 0.5" />
            </geometry>
            <material name="Blue">
                <color rgba="0 0.0 1.0 1.0"/>
            </material>
        </visual>
        <collision>
            <origin xyz="0.0 0.0 -0.25" rpy="0 0 0"/>
            <geometry>
                <box size="0.2697420647060007 0.8322819496741144 0.5" />
            </geometry>
        </collision>
    </link>
</robot>