<robot name = "robot">
    <link name="Body0">
        <inertial>
            <origin xyz="2.0 0.0 0.5" rpy="0 0 0"/>
            <mass value="1" />
            <inertia ixx="100" ixy="0" ixz="0" iyy="100" iyz="0" izz="100" />
        </inertial>
        <visual>
            <origin xyz="2.0 0.0 0.5" rpy="0 0 0"/>
            <geometry>
                <box size="0.5768442370087475 0.2341030456654396 0.3114277621222691" />
            </geometry>
            <material name="Blue">
                <color rgba="0 0.0 1.0 1.0"/>
            </material>
        </visual>
        <collision>
            <origin xyz="2.0 0.0 0.5" rpy="0 0 0"/>
            <geometry>
                <box size="0.5768442370087475 0.2341030456654396 0.3114277621222691" />
            </geometry>
        </collision>
    </link>
    <joint name="Body0_Body1" type="revolute">
       <parent link="Body0"/>
       <child  link="Body1"/>
       <origin rpy="0 0 0" xyz="1.7115778814956262 0.0 0.5" />
     <axis xyz="0 1 0"/>
       <limit effort="0.0" lower="-3.14159" upper="3.14159" velocity="0.0"/>
    </joint>
    <link name="Body1">
        <inertial>
            <origin xyz="-1.2082811836709009 0.0 0.0" rpy="0 0 0"/>
            <mass value="1" />
            <inertia ixx="100" ixy="0" ixz="0" iyy="100" iyz="0" izz="100" />
        </inertial>
        <visual>
            <origin xyz="-1.2082811836709009 0.0 0.0" rpy="0 0 0"/>
            <geometry>
                <box size="2.4165623673418017 0.5882980702318752 0.443183993097494" />
            </geometry>
            <material name="Blue">
                <color rgba="0 0.0 1.0 1.0"/>
            </material>
        </visual>
        <collision>
            <origin xyz="-1.2082811836709009 0.0 0.0" rpy="0 0 0"/>
            <geometry>
                <box size="2.4165623673418017 0.5882980702318752 0.443183993097494" />
            </geometry>
        </collision>
    </link>
    <joint name="Body1_Body2" type="revolute">
       <parent link="Body1"/>
       <child  link="Body2"/>
       <origin rpy="0 0 0" xyz="-1.2082811836709009 -0.2941490351159376 0.0" />
     <axis xyz="0 1 0"/>
       <limit effort="0.0" lower="-3.14159" upper="3.14159" velocity="0.0"/>
    </joint>
    <link name="Body2">
        <inertial>
            <origin xyz="0.0 -0.39455939487337766 0.0" rpy="0 0 0"/>
            <mass value="1" />
            <inertia ixx="100" ixy="0" ixz="0" iyy="100" iyz="0" izz="100" />
        </inertial>
        <visual>
            <origin xyz="0.0 -0.39455939487337766 0.0" rpy="0 0 0"/>
            <geometry>
                <box size="1.0037635906342752 0.7891187897467553 0.21528863989796376" />
            </geometry>
            <material name="Blue">
                <color rgba="0 0.0 1.0 1.0"/>
            </material>
        </visual>
        <collision>
            <origin xyz="0.0 -0.39455939487337766 0.0" rpy="0 0 0"/>
            <geometry>
                <box size="1.0037635906342752 0.7891187897467553 0.21528863989796376" />
            </geometry>
        </collision>
    </link>
    <joint name="Body2_Body3" type="revolute">
       <parent link="Body2"/>
       <child  link="Body3"/>
       <origin rpy="0 0 0" xyz="0.0 -0.7891187897467553 0.0" />
     <axis xyz="0 0 1"/>
       <limit effort="0.0" lower="-3.14159" upper="3.14159" velocity="0.0"/>
    </joint>
    <link name="Body3">
        <inertial>
            <origin xyz="0.0 0.0 -0.25" rpy="0 0 0"/>
            <mass value="1" />
            <inertia ixx="100" ixy="0" ixz="0" iyy="100" iyz="0" izz="100" />
        </inertial>
        <visual>
            <origin xyz="0.0 0.0 -0.25" rpy="0 0 0"/>
            <geometry>
                <box size="1.0037635906342752 0.39455939487337766 0.5" />
            </geometry>
            <material name="Blue">
                <color rgba="0 0.0 1.0 1.0"/>
            </material>
        </visual>
        <collision>
            <origin xyz="0.0 0.0 -0.25" rpy="0 0 0"/>
            <geometry>
                <box size="1.0037635906342752 0.39455939487337766 0.5" />
            </geometry>
        </collision>
    </link>
    <joint name="Body3_Body4" type="revolute">
       <parent link="Body3"/>
       <child  link="Body4"/>
       <origin rpy="0 0 0" xyz="0.0 1.3774168599786305 0.0" />
     <axis xyz="0 0 1"/>
       <limit effort="0.0" lower="-3.14159" upper="3.14159" velocity="0.0"/>
    </joint>
    <link name="Body4">
        <inertial>
            <origin xyz="0.0 0.7039418662837057 0.0" rpy="0 0 0"/>
            <mass value="1" />
            <inertia ixx="100" ixy="0" ixz="0" iyy="100" iyz="0" izz="100" />
        </inertial>
        <visual>
            <origin xyz="0.0 0.7039418662837057 0.0" rpy="0 0 0"/>
            <geometry>
                <box size="0.09994915012065184 1.4078837325674114 0.08546226530251347" />
            </geometry>
            <material name="Blue">
                <color rgba="0 0.0 1.0 1.0"/>
            </material>
        </visual>
        <collision>
            <origin xyz="0.0 0.7039418662837057 0.0" rpy="0 0 0"/>
            <geometry>
                <box size="0.09994915012065184 1.4078837325674114 0.08546226530251347" />
            </geometry>
        </collision>
    </link>
    <joint name="Body4_Body5" type="revolute">
       <parent link="Body4"/>
       <child  link="Body5"/>
       <origin rpy="0 0 0" xyz="0.0 1.4078837325674114 0.0" />
     <axis xyz="0 0 1"/>
       <limit effort="0.0" lower="-3.14159" upper="3.14159" velocity="0.0"/>
    </joint>
    <link name="Body5">
        <inertial>
            <origin xyz="0.0 0.0 -0.25" rpy="0 0 0"/>
            <mass value="1" />
            <inertia ixx="100" ixy="0" ixz="0" iyy="100" iyz="0" izz="100" />
        </inertial>
        <visual>
            <origin xyz="0.0 0.0 -0.25" rpy="0 0 0"/>
            <geometry>
                <box size="0.09994915012065184 0.7039418662837057 0.5" />
            </geometry>
            <material name="Blue">
                <color rgba="0 0.0 1.0 1.0"/>
            </material>
        </visual>
        <collision>
            <origin xyz="0.0 0.0 -0.25" rpy="0 0 0"/>
            <geometry>
                <box size="0.09994915012065184 0.7039418662837057 0.5" />
            </geometry>
        </collision>
    </link>
    <joint name="Body5_Body6" type="revolute">
       <parent link="Body5"/>
       <child  link="Body6"/>
       <origin rpy="0 0 0" xyz="-1.2082811836709009 -1.7020327676833489 0.0" />
     <axis xyz="0 1 0"/>
       <limit effort="0.0" lower="-3.14159" upper="3.14159" velocity="0.0"/>
    </joint>
    <link name="Body6">
        <inertial>
            <origin xyz="-1.3083726008385743 0.0 0.0" rpy="0 0 0"/>
            <mass value="1" />
            <inertia ixx="100" ixy="0" ixz="0" iyy="100" iyz="0" izz="100" />
        </inertial>
        <visual>
            <origin xyz="-1.3083726008385743 0.0 0.0" rpy="0 0 0"/>
            <geometry>
                <box size="2.6167452016771486 0.9346169810515088 0.22742040810752284" />
            </geometry>
            <material name="Blue">
                <color rgba="0 0.0 1.0 1.0"/>
            </material>
        </visual>
        <collision>
            <origin xyz="-1.3083726008385743 0.0 0.0" rpy="0 0 0"/>
            <geometry>
                <box size="2.6167452016771486 0.9346169810515088 0.22742040810752284" />
            </geometry>
        </collision>
    </link>
    <joint name="Body6_Body7" type="revolute">
       <parent link="Body6"/>
       <child  link="Body7"/>
       <origin rpy="0 0 0" xyz="-1.3083726008385743 -0.4673084905257544 0.0" />
     <axis xyz="0 1 0"/>
       <limit effort="0.0" lower="-3.14159" upper="3.14159" velocity="0.0"/>
    </joint>
    <link name="Body7">
        <inertial>
            <origin xyz="0.0 -0.12288975429254456 0.0" rpy="0 0 0"/>
            <mass value="1" />
            <inertia ixx="100" ixy="0" ixz="0" iyy="100" iyz="0" izz="100" />
        </inertial>
        <visual>
            <origin xyz="0.0 -0.12288975429254456 0.0" rpy="0 0 0"/>
            <geometry>
                <box size="0.8236416471054655 0.24577950858508912 0.078648085873308" />
            </geometry>
            <material name="Green">
                <color rgba="0 1.0 0.0 1.0"/>
            </material>
        </visual>
        <collision>
            <origin xyz="0.0 -0.12288975429254456 0.0" rpy="0 0 0"/>
            <geometry>
                <box size="0.8236416471054655 0.24577950858508912 0.078648085873308" />
            </geometry>
        </collision>
    </link>
    <joint name="Body7_Body8" type="revolute">
       <parent link="Body7"/>
       <child  link="Body8"/>
       <origin rpy="0 0 0" xyz="0.0 -0.24577950858508912 0.0" />
     <axis xyz="0 0 1"/>
       <limit effort="0.0" lower="-3.14159" upper="3.14159" velocity="0.0"/>
    </joint>
    <link name="Body8">
        <inertial>
            <origin xyz="0.0 0.0 -0.25" rpy="0 0 0"/>
            <mass value="1" />
            <inertia ixx="100" ixy="0" ixz="0" iyy="100" iyz="0" izz="100" />
        </inertial>
        <visual>
            <origin xyz="0.0 0.0 -0.25" rpy="0 0 0"/>
            <geometry>
                <box size="0.8236416471054655 0.12288975429254456 0.5" />
            </geometry>
            <material name="Blue">
                <color rgba="0 0.0 1.0 1.0"/>
            </material>
        </visual>
        <collision>
            <origin xyz="0.0 0.0 -0.25" rpy="0 0 0"/>
            <geometry>
                <box size="0.8236416471054655 0.12288975429254456 0.5" />
            </geometry>
        </collision>
    </link>
    <joint name="Body8_Body9" type="revolute">
       <parent link="Body8"/>
       <child  link="Body9"/>
       <origin rpy="0 0 0" xyz="0.0 1.180396489636598 0.0" />
     <axis xyz="0 0 1"/>
       <limit effort="0.0" lower="-3.14159" upper="3.14159" velocity="0.0"/>
    </joint>
    <link name="Body9">
        <inertial>
            <origin xyz="0.0 0.6459116683127886 0.0" rpy="0 0 0"/>
            <mass value="1" />
            <inertia ixx="100" ixy="0" ixz="0" iyy="100" iyz="0" izz="100" />
        </inertial>
        <visual>
            <origin xyz="0.0 0.6459116683127886 0.0" rpy="0 0 0"/>
            <geometry>
                <box size="1.0899427556885668 1.2918233366255771 0.15553117261683602" />
            </geometry>
            <material name="Blue">
                <color rgba="0 0.0 1.0 1.0"/>
            </material>
        </visual>
        <collision>
            <origin xyz="0.0 0.6459116683127886 0.0" rpy="0 0 0"/>
            <geometry>
                <box size="1.0899427556885668 1.2918233366255771 0.15553117261683602" />
            </geometry>
        </collision>
    </link>
    <joint name="Body9_Body10" type="revolute">
       <parent link="Body9"/>
       <child  link="Body10"/>
       <origin rpy="0 0 0" xyz="0.0 1.2918233366255771 0.0" />
     <axis xyz="0 0 1"/>
       <limit effort="0.0" lower="-3.14159" upper="3.14159" velocity="0.0"/>
    </joint>
    <link name="Body10">
        <inertial>
            <origin xyz="0.0 0.0 -0.25" rpy="0 0 0"/>
            <mass value="1" />
            <inertia ixx="100" ixy="0" ixz="0" iyy="100" iyz="0" izz="100" />
        </inertial>
        <visual>
            <origin xyz="0.0 0.0 -0.25" rpy="0 0 0"/>
            <geometry>
                <box size="1.0899427556885668 0.6459116683127886 0.5" />
            </geometry>
            <material name="Blue">
                <color rgba="0 0.0 1.0 1.0"/>
            </material>
        </visual>
        <collision>
            <origin xyz="0.0 0.0 -0.25" rpy="0 0 0"/>
            <geometry>
                <box size="1.0899427556885668 0.6459116683127886 0.5" />
            </geometry>
        </collision>
    </link>
    <joint name="Body10_Body11" type="revolute">
       <parent link="Body10"/>
       <child  link="Body11"/>
       <origin rpy="0 0 0" xyz="-1.3083726008385743 -1.7591318271513314 0.0" />
     <axis xyz="0 1 0"/>
       <limit effort="0.0" lower="-3.14159" upper="3.14159" velocity="0.0"/>
    </joint>
    <link name="Body11">
        <inertial>
            <origin xyz="-1.1666586686036957 0.0 0.0" rpy="0 0 0"/>
            <mass value="1" />
            <inertia ixx="100" ixy="0" ixz="0" iyy="100" iyz="0" izz="100" />
        </inertial>
        <visual>
            <origin xyz="-1.1666586686036957 0.0 0.0" rpy="0 0 0"/>
            <geometry>
                <box size="2.3333173372073914 0.9943426695400583 0.5144846694451446" />
            </geometry>
            <material name="Green">
                <color rgba="0 1.0 0.0 1.0"/>
            </material>
        </visual>
        <collision>
            <origin xyz="-1.1666586686036957 0.0 0.0" rpy="0 0 0"/>
            <geometry>
                <box size="2.3333173372073914 0.9943426695400583 0.5144846694451446" />
            </geometry>
        </collision>
    </link>
    <joint name="Body11_Body12" type="revolute">
       <parent link="Body11"/>
       <child  link="Body12"/>
       <origin rpy="0 0 0" xyz="-1.1666586686036957 -0.49717133477002917 0.0" />
     <axis xyz="0 1 0"/>
       <limit effort="0.0" lower="-3.14159" upper="3.14159" velocity="0.0"/>
    </joint>
    <link name="Body12">
        <inertial>
            <origin xyz="0.0 -0.5563129233457322 0.0" rpy="0 0 0"/>
            <mass value="1" />
            <inertia ixx="100" ixy="0" ixz="0" iyy="100" iyz="0" izz="100" />
        </inertial>
        <visual>
            <origin xyz="0.0 -0.5563129233457322 0.0" rpy="0 0 0"/>
            <geometry>
                <box size="0.9210809389695849 1.1126258466914645 0.20283383790344775" />
            </geometry>
            <material name="Green">
                <color rgba="0 1.0 0.0 1.0"/>
            </material>
        </visual>
        <collision>
            <origin xyz="0.0 -0.5563129233457322 0.0" rpy="0 0 0"/>
            <geometry>
                <box size="0.9210809389695849 1.1126258466914645 0.20283383790344775" />
            </geometry>
        </collision>
    </link>
    <joint name="Body12_Body13" type="revolute">
       <parent link="Body12"/>
       <child  link="Body13"/>
       <origin rpy="0 0 0" xyz="0.0 -1.1126258466914645 0.0" />
     <axis xyz="0 0 1"/>
       <limit effort="0.0" lower="-3.14159" upper="3.14159" velocity="0.0"/>
    </joint>
    <link name="Body13">
        <inertial>
            <origin xyz="0.0 0.0 -0.25" rpy="0 0 0"/>
            <mass value="1" />
            <inertia ixx="100" ixy="0" ixz="0" iyy="100" iyz="0" izz="100" />
        </inertial>
        <visual>
            <origin xyz="0.0 0.0 -0.25" rpy="0 0 0"/>
            <geometry>
                <box size="0.9210809389695849 0.5563129233457322 0.5" />
            </geometry>
            <material name="Blue">
                <color rgba="0 0.0 1.0 1.0"/>
            </material>
        </visual>
        <collision>
            <origin xyz="0.0 0.0 -0.25" rpy="0 0 0"/>
            <geometry>
                <box size="0.9210809389695849 0.5563129233457322 0.5" />
            </geometry>
        </collision>
    </link>
    <joint name="Body13_Body14" type="revolute">
       <parent link="Body13"/>
       <child  link="Body14"/>
       <origin rpy="0 0 0" xyz="0.0 2.1069685162315226 0.0" />
     <axis xyz="0 0 1"/>
       <limit effort="0.0" lower="-3.14159" upper="3.14159" velocity="0.0"/>
    </joint>
    <link name="Body14">
        <inertial>
            <origin xyz="0.0 0.5608864466749035 0.0" rpy="0 0 0"/>
            <mass value="1" />
            <inertia ixx="100" ixy="0" ixz="0" iyy="100" iyz="0" izz="100" />
        </inertial>
        <visual>
            <origin xyz="0.0 0.5608864466749035 0.0" rpy="0 0 0"/>
            <geometry>
                <box size="0.5128233002150917 1.121772893349807 0.27970323376972117" />
            </geometry>
            <material name="Blue">
                <color rgba="0 0.0 1.0 1.0"/>
            </material>
        </visual>
        <collision>
            <origin xyz="0.0 0.5608864466749035 0.0" rpy="0 0 0"/>
            <geometry>
                <box size="0.5128233002150917 1.121772893349807 0.27970323376972117" />
            </geometry>
        </collision>
    </link>
    <joint name="Body14_Body15" type="revolute">
       <parent link="Body14"/>
       <child  link="Body15"/>
       <origin rpy="0 0 0" xyz="0.0 1.121772893349807 0.0" />
     <axis xyz="0 0 1"/>
       <limit effort="0.0" lower="-3.14159" upper="3.14159" velocity="0.0"/>
    </joint>
    <link name="Body15">
        <inertial>
            <origin xyz="0.0 0.0 -0.25" rpy="0 0 0"/>
            <mass value="1" />
            <inertia ixx="100" ixy="0" ixz="0" iyy="100" iyz="0" izz="100" />
        </inertial>
        <visual>
            <origin xyz="0.0 0.0 -0.25" rpy="0 0 0"/>
            <geometry>
                <box size="0.5128233002150917 0.5608864466749035 0.5" />
            </geometry>
            <material name="Blue">
                <color rgba="0 0.0 1.0 1.0"/>
            </material>
        </visual>
        <collision>
            <origin xyz="0.0 0.0 -0.25" rpy="0 0 0"/>
            <geometry>
                <box size="0.5128233002150917 0.5608864466749035 0.5" />
            </geometry>
        </collision>
    </link>
</robot>