<robot name = "robot">
    <link name="spine0">
        <inertial>
            <origin xyz="2.0 0.0 0.5" rpy="0 0 0"/>
            <mass value="1" />
            <inertia ixx="100" ixy="0" ixz="0" iyy="100" iyz="0" izz="100" />
        </inertial>
        <visual>
            <origin xyz="2.0 0.0 0.5" rpy="0 0 0"/>
            <geometry>
                <box size="0.8069546836053825 0.653176338139039 0.38710176679404984" />
            </geometry>
            <material name="Cyan">
                <color rgba="0 1.0 1.0 1.0"/>
            </material>
        </visual>
        <collision>
            <origin xyz="2.0 0.0 0.5" rpy="0 0 0"/>
            <geometry>
                <box size="0.8069546836053825 0.653176338139039 0.38710176679404984" />
            </geometry>
        </collision>
    </link>
    <joint name="spine0_arm0" type="revolute">
       <parent link="spine0"/>
       <child  link="arm0"/>
       <origin rpy="0 0 0" xyz="2.0 -0.3265881690695195 0.5" />
     <axis xyz="0 1 0"/>
       <limit effort="0.0" lower="-3.14159" upper="3.14159" velocity="0.0"/>
    </joint>
    <link name="arm0">
        <inertial>
            <origin xyz="0.0 -0.15 0.0" rpy="0 0 0"/>
            <mass value="1" />
            <inertia ixx="100" ixy="0" ixz="0" iyy="100" iyz="0" izz="100" />
        </inertial>
        <visual>
            <origin xyz="0.0 -0.15 0.0" rpy="0 0 0"/>
            <geometry>
                <box size="0.5792859879551486 0.3 0.7244600204866894" />
            </geometry>
            <material name="Cyan">
                <color rgba="0 1.0 1.0 1.0"/>
            </material>
        </visual>
        <collision>
            <origin xyz="0.0 -0.15 0.0" rpy="0 0 0"/>
            <geometry>
                <box size="0.5792859879551486 0.3 0.7244600204866894" />
            </geometry>
        </collision>
    </link>
    <joint name="spine0_spine1" type="revolute">
       <parent link="spine0"/>
       <child  link="spine1"/>
       <origin rpy="0 0 0" xyz="1.5965226581973089 0.0 0.5" />
     <axis xyz="0 1 0"/>
       <limit effort="0.0" lower="-3.14159" upper="3.14159" velocity="0.0"/>
    </joint>
    <link name="spine1">
        <inertial>
            <origin xyz="-0.28117006340990786 0.0 0.0" rpy="0 0 0"/>
            <mass value="1" />
            <inertia ixx="100" ixy="0" ixz="0" iyy="100" iyz="0" izz="100" />
        </inertial>
        <visual>
            <origin xyz="-0.28117006340990786 0.0 0.0" rpy="0 0 0"/>
            <geometry>
                <box size="0.5623401268198157 0.3 0.5899821646868635" />
            </geometry>
            <material name="Cyan">
                <color rgba="0 1.0 1.0 1.0"/>
            </material>
        </visual>
        <collision>
            <origin xyz="-0.28117006340990786 0.0 0.0" rpy="0 0 0"/>
            <geometry>
                <box size="0.5623401268198157 0.3 0.5899821646868635" />
            </geometry>
        </collision>
    </link>
</robot>