<robot name = "robot">
    <link name="spine0">
        <inertial>
            <origin xyz="0 0 1" rpy="0 0 0"/>
            <mass value="1" />
            <inertia ixx="100" ixy="0" ixz="0" iyy="100" iyz="0" izz="100" />
        </inertial>
        <visual>
            <origin xyz="0 0 1" rpy="0 0 0"/>
            <geometry>
                <box size="0.4664024096415692 0.5982631966813283 0.3" />
            </geometry>
            <material name="Cyan">
                <color rgba="0 1.0 1.0 1.0"/>
            </material>
        </visual>
        <collision>
            <origin xyz="0 0 1" rpy="0 0 0"/>
            <geometry>
                <box size="0.4664024096415692 0.5982631966813283 0.3" />
            </geometry>
        </collision>
    </link>
    <joint name="spine0_arm0" type="revolute">
       <parent link="spine0"/>
       <child  link="arm0"/>
       <origin rpy="0 0 0" xyz="0.0 -0.29913159834066416 1.0" />
     <axis xyz="0 1 0"/>
       <limit effort="0.0" lower="-3.14159" upper="3.14159" velocity="0.0"/>
    </joint>
    <link name="arm0">
        <inertial>
            <origin xyz="0.0 -0.09006961481914784 0.0" rpy="0 0 0"/>
            <mass value="1" />
            <inertia ixx="100" ixy="0" ixz="0" iyy="100" iyz="0" izz="100" />
        </inertial>
        <visual>
            <origin xyz="0.0 -0.09006961481914784 0.0" rpy="0 0 0"/>
            <geometry>
                <box size="0.2019610443228552 0.18013922963829568 0.09" />
            </geometry>
            <material name="Cyan">
                <color rgba="0 1.0 1.0 1.0"/>
            </material>
        </visual>
        <collision>
            <origin xyz="0.0 -0.09006961481914784 0.0" rpy="0 0 0"/>
            <geometry>
                <box size="0.2019610443228552 0.18013922963829568 0.09" />
            </geometry>
        </collision>
    </link>
    <joint name="arm0_leg0" type="revolute">
       <parent link="arm0"/>
       <child  link="leg0"/>
       <origin rpy="0 0 0" xyz="0.0 -0.18013922963829568 0.0" />
     <axis xyz="0 1 0"/>
       <limit effort="0.0" lower="-3.14159" upper="3.14159" velocity="0.0"/>
    </joint>
    <link name="leg0">
        <inertial>
            <origin xyz="0.0 0.0 0.10660126098805678" rpy="0 0 0"/>
            <mass value="1" />
            <inertia ixx="100" ixy="0" ixz="0" iyy="100" iyz="0" izz="100" />
        </inertial>
        <visual>
            <origin xyz="0.0 0.0 0.10660126098805678" rpy="0 0 0"/>
            <geometry>
                <box size="0.1514707832421414 0.13510442222872177 0.21320252197611356" />
            </geometry>
            <material name="Cyan">
                <color rgba="0 1.0 1.0 1.0"/>
            </material>
        </visual>
        <collision>
            <origin xyz="0.0 0.0 0.10660126098805678" rpy="0 0 0"/>
            <geometry>
                <box size="0.1514707832421414 0.13510442222872177 0.21320252197611356" />
            </geometry>
        </collision>
    </link>
    <joint name="spine0_arm1" type="revolute">
       <parent link="spine0"/>
       <child  link="arm1"/>
       <origin rpy="0 0 0" xyz="0.0 0.29913159834066416 1.0" />
     <axis xyz="0 1 0"/>
       <limit effort="0.0" lower="-3.14159" upper="3.14159" velocity="0.0"/>
    </joint>
    <link name="arm1">
        <inertial>
            <origin xyz="0.0 0.08973947950219925 0.0" rpy="0 0 0"/>
            <mass value="1" />
            <inertia ixx="100" ixy="0" ixz="0" iyy="100" iyz="0" izz="100" />
        </inertial>
        <visual>
            <origin xyz="0.0 0.08973947950219925 0.0" rpy="0 0 0"/>
            <geometry>
                <box size="0.1719555295365369 0.1794789590043985 0.09" />
            </geometry>
            <material name="Cyan">
                <color rgba="0 1.0 1.0 1.0"/>
            </material>
        </visual>
        <collision>
            <origin xyz="0.0 0.08973947950219925 0.0" rpy="0 0 0"/>
            <geometry>
                <box size="0.1719555295365369 0.1794789590043985 0.09" />
            </geometry>
        </collision>
    </link>
</robot>