<robot name = "robot">
    <link name="spine0">
        <inertial>
            <origin xyz="0 0 1" rpy="0 0 0"/>
            <mass value="1" />
            <inertia ixx="100" ixy="0" ixz="0" iyy="100" iyz="0" izz="100" />
        </inertial>
        <visual>
            <origin xyz="0 0 1" rpy="0 0 0"/>
            <geometry>
                <box size="0.3 0.7009437087920675 0.7331574443624942" />
            </geometry>
            <material name="Cyan">
                <color rgba="0 1.0 1.0 1.0"/>
            </material>
        </visual>
        <collision>
            <origin xyz="0 0 1" rpy="0 0 0"/>
            <geometry>
                <box size="0.3 0.7009437087920675 0.7331574443624942" />
            </geometry>
        </collision>
    </link>
    <joint name="spine0_arm0" type="revolute">
       <parent link="spine0"/>
       <child  link="arm0"/>
       <origin rpy="0 0 0" xyz="0.0 0.35047185439603373 1.0" />
     <axis xyz="0 1 0"/>
       <limit effort="0.0" lower="-3.14159" upper="3.14159" velocity="0.0"/>
    </joint>
    <link name="arm0">
        <inertial>
            <origin xyz="0.0 0.26209207813230984 0.0" rpy="0 0 0"/>
            <mass value="1" />
            <inertia ixx="100" ixy="0" ixz="0" iyy="100" iyz="0" izz="100" />
        </inertial>
        <visual>
            <origin xyz="0.0 0.26209207813230984 0.0" rpy="0 0 0"/>
            <geometry>
                <box size="0.12504614057212446 0.5241841562646197 0.2379076709988168" />
            </geometry>
            <material name="Cyan">
                <color rgba="0 1.0 1.0 1.0"/>
            </material>
        </visual>
        <collision>
            <origin xyz="0.0 0.26209207813230984 0.0" rpy="0 0 0"/>
            <geometry>
                <box size="0.12504614057212446 0.5241841562646197 0.2379076709988168" />
            </geometry>
        </collision>
    </link>
    <joint name="arm0_leg0" type="revolute">
       <parent link="arm0"/>
       <child  link="leg0"/>
       <origin rpy="0 0 0" xyz="0.0 0.5241841562646197 0.0" />
     <axis xyz="0 1 0"/>
       <limit effort="0.0" lower="-3.14159" upper="3.14159" velocity="0.0"/>
    </joint>
    <link name="leg0">
        <inertial>
            <origin xyz="0.0 0.0 -0.48218819348480807" rpy="0 0 0"/>
            <mass value="1" />
            <inertia ixx="100" ixy="0" ixz="0" iyy="100" iyz="0" izz="100" />
        </inertial>
        <visual>
            <origin xyz="0.0 0.0 -0.48218819348480807" rpy="0 0 0"/>
            <geometry>
                <box size="0.09378460542909334 0.39313811719846475 0.9643763869696161" />
            </geometry>
            <material name="Cyan">
                <color rgba="0 1.0 1.0 1.0"/>
            </material>
        </visual>
        <collision>
            <origin xyz="0.0 0.0 -0.48218819348480807" rpy="0 0 0"/>
            <geometry>
                <box size="0.09378460542909334 0.39313811719846475 0.9643763869696161" />
            </geometry>
        </collision>
    </link>
    <joint name="spine0_spine1" type="revolute">
       <parent link="spine0"/>
       <child  link="spine1"/>
       <origin rpy="0 0 0" xyz="-0.15 0.0 1.0" />
     <axis xyz="0 1 0"/>
       <limit effort="0.0" lower="-3.14159" upper="3.14159" velocity="0.0"/>
    </joint>
    <link name="spine1">
        <inertial>
            <origin xyz="-0.2165348986387648 0.0 0.0" rpy="0 0 0"/>
            <mass value="1" />
            <inertia ixx="100" ixy="0" ixz="0" iyy="100" iyz="0" izz="100" />
        </inertial>
        <visual>
            <origin xyz="-0.2165348986387648 0.0 0.0" rpy="0 0 0"/>
            <geometry>
                <box size="0.4330697972775296 0.7675497299978131 0.9497022499041303" />
            </geometry>
            <material name="Cyan">
                <color rgba="0 1.0 1.0 1.0"/>
            </material>
        </visual>
        <collision>
            <origin xyz="-0.2165348986387648 0.0 0.0" rpy="0 0 0"/>
            <geometry>
                <box size="0.4330697972775296 0.7675497299978131 0.9497022499041303" />
            </geometry>
        </collision>
    </link>
</robot>