<robot name = "robot">
    <link name="spine0">
        <inertial>
            <origin xyz="0 0 1" rpy="0 0 0"/>
            <mass value="1" />
            <inertia ixx="100" ixy="0" ixz="0" iyy="100" iyz="0" izz="100" />
        </inertial>
        <visual>
            <origin xyz="0 0 1" rpy="0 0 0"/>
            <geometry>
                <box size="0.3 0.3 0.9396128885336229" />
            </geometry>
            <material name="Cyan">
                <color rgba="0 1.0 1.0 1.0"/>
            </material>
        </visual>
        <collision>
            <origin xyz="0 0 1" rpy="0 0 0"/>
            <geometry>
                <box size="0.3 0.3 0.9396128885336229" />
            </geometry>
        </collision>
    </link>
    <joint name="spine0_arm0" type="revolute">
       <parent link="spine0"/>
       <child  link="arm0"/>
       <origin rpy="0 0 0" xyz="0.0 0.15 1.0" />
     <axis xyz="0 1 0"/>
       <limit effort="0.0" lower="-3.14159" upper="3.14159" velocity="0.0"/>
    </joint>
    <link name="arm0">
        <inertial>
            <origin xyz="0.0 0.058348392302860916 0.0" rpy="0 0 0"/>
            <mass value="1" />
            <inertia ixx="100" ixy="0" ixz="0" iyy="100" iyz="0" izz="100" />
        </inertial>
        <visual>
            <origin xyz="0.0 0.058348392302860916 0.0" rpy="0 0 0"/>
            <geometry>
                <box size="0.2815364895370683 0.11669678460572183 0.28188386656008685" />
            </geometry>
            <material name="Cyan">
                <color rgba="0 1.0 1.0 1.0"/>
            </material>
        </visual>
        <collision>
            <origin xyz="0.0 0.058348392302860916 0.0" rpy="0 0 0"/>
            <geometry>
                <box size="0.2815364895370683 0.11669678460572183 0.28188386656008685" />
            </geometry>
        </collision>
    </link>
    <joint name="spine0_spine1" type="revolute">
       <parent link="spine0"/>
       <child  link="spine1"/>
       <origin rpy="0 0 0" xyz="-0.15 0.0 1.0" />
     <axis xyz="0 1 0"/>
       <limit effort="0.0" lower="-3.14159" upper="3.14159" velocity="0.0"/>
    </joint>
    <link name="spine1">
        <inertial>
            <origin xyz="-0.3100284561060911 0.0 0.0" rpy="0 0 0"/>
            <mass value="1" />
            <inertia ixx="100" ixy="0" ixz="0" iyy="100" iyz="0" izz="100" />
        </inertial>
        <visual>
            <origin xyz="-0.3100284561060911 0.0 0.0" rpy="0 0 0"/>
            <geometry>
                <box size="0.6200569122121822 0.685336187306129 0.35376088184098686" />
            </geometry>
            <material name="Cyan">
                <color rgba="0 1.0 1.0 1.0"/>
            </material>
        </visual>
        <collision>
            <origin xyz="-0.3100284561060911 0.0 0.0" rpy="0 0 0"/>
            <geometry>
                <box size="0.6200569122121822 0.685336187306129 0.35376088184098686" />
            </geometry>
        </collision>
    </link>
    <joint name="spine1_arm1" type="revolute">
       <parent link="spine1"/>
       <child  link="arm1"/>
       <origin rpy="0 0 0" xyz="-0.3100284561060911 0.3426680936530645 0.0" />
     <axis xyz="0 1 0"/>
       <limit effort="0.0" lower="-3.14159" upper="3.14159" velocity="0.0"/>
    </joint>
    <link name="arm1">
        <inertial>
            <origin xyz="0.0 0.27561326331253316 0.0" rpy="0 0 0"/>
            <mass value="1" />
            <inertia ixx="100" ixy="0" ixz="0" iyy="100" iyz="0" izz="100" />
        </inertial>
        <visual>
            <origin xyz="0.0 0.27561326331253316 0.0" rpy="0 0 0"/>
            <geometry>
                <box size="0.18601707366365464 0.5512265266250663 0.2750058498965505" />
            </geometry>
            <material name="Cyan">
                <color rgba="0 1.0 1.0 1.0"/>
            </material>
        </visual>
        <collision>
            <origin xyz="0.0 0.27561326331253316 0.0" rpy="0 0 0"/>
            <geometry>
                <box size="0.18601707366365464 0.5512265266250663 0.2750058498965505" />
            </geometry>
        </collision>
    </link>
</robot>