<robot name = "robot">
    <link name="spine0">
        <inertial>
            <origin xyz="0 0 1" rpy="0 0 0"/>
            <mass value="1" />
            <inertia ixx="100" ixy="0" ixz="0" iyy="100" iyz="0" izz="100" />
        </inertial>
        <visual>
            <origin xyz="0 0 1" rpy="0 0 0"/>
            <geometry>
                <box size="0.9660302438929285 0.7366808227567342 0.46172830002600207" />
            </geometry>
            <material name="Cyan">
                <color rgba="0 1.0 1.0 1.0"/>
            </material>
        </visual>
        <collision>
            <origin xyz="0 0 1" rpy="0 0 0"/>
            <geometry>
                <box size="0.9660302438929285 0.7366808227567342 0.46172830002600207" />
            </geometry>
        </collision>
    </link>
    <joint name="spine0_arm0" type="revolute">
       <parent link="spine0"/>
       <child  link="arm0"/>
       <origin rpy="0 0 0" xyz="0.0 0.3683404113783671 1.0" />
     <axis xyz="0 1 0"/>
       <limit effort="0.0" lower="-3.14159" upper="3.14159" velocity="0.0"/>
    </joint>
    <link name="arm0">
        <inertial>
            <origin xyz="0.0 0.34006456999855583 0.0" rpy="0 0 0"/>
            <mass value="1" />
            <inertia ixx="100" ixy="0" ixz="0" iyy="100" iyz="0" izz="100" />
        </inertial>
        <visual>
            <origin xyz="0.0 0.34006456999855583 0.0" rpy="0 0 0"/>
            <geometry>
                <box size="0.2898090731678785 0.6801291399971117 0.34995752966318394" />
            </geometry>
            <material name="Cyan">
                <color rgba="0 1.0 1.0 1.0"/>
            </material>
        </visual>
        <collision>
            <origin xyz="0.0 0.34006456999855583 0.0" rpy="0 0 0"/>
            <geometry>
                <box size="0.2898090731678785 0.6801291399971117 0.34995752966318394" />
            </geometry>
        </collision>
    </link>
    <joint name="arm0_leg0" type="revolute">
       <parent link="arm0"/>
       <child  link="leg0"/>
       <origin rpy="0 0 0" xyz="0.0 0.6801291399971117 0.0" />
     <axis xyz="0 1 0"/>
       <limit effort="0.0" lower="-3.14159" upper="3.14159" velocity="0.0"/>
    </joint>
    <link name="leg0">
        <inertial>
            <origin xyz="0.0 0.0 -0.26425440818542273" rpy="0 0 0"/>
            <mass value="1" />
            <inertia ixx="100" ixy="0" ixz="0" iyy="100" iyz="0" izz="100" />
        </inertial>
        <visual>
            <origin xyz="0.0 0.0 -0.26425440818542273" rpy="0 0 0"/>
            <geometry>
                <box size="0.2173568048759089 0.6648952151678749 0.5285088163708455" />
            </geometry>
            <material name="Cyan">
                <color rgba="0 1.0 1.0 1.0"/>
            </material>
        </visual>
        <collision>
            <origin xyz="0.0 0.0 -0.26425440818542273" rpy="0 0 0"/>
            <geometry>
                <box size="0.2173568048759089 0.6648952151678749 0.5285088163708455" />
            </geometry>
        </collision>
    </link>
    <joint name="spine0_spine1" type="revolute">
       <parent link="spine0"/>
       <child  link="spine1"/>
       <origin rpy="0 0 0" xyz="-0.48301512194646423 0.0 1.0" />
     <axis xyz="0 1 0"/>
       <limit effort="0.0" lower="-3.14159" upper="3.14159" velocity="0.0"/>
    </joint>
    <link name="spine1">
        <inertial>
            <origin xyz="-0.354198768829377 0.0 0.0" rpy="0 0 0"/>
            <mass value="1" />
            <inertia ixx="100" ixy="0" ixz="0" iyy="100" iyz="0" izz="100" />
        </inertial>
        <visual>
            <origin xyz="-0.354198768829377 0.0 0.0" rpy="0 0 0"/>
            <geometry>
                <box size="0.708397537658754 0.7898101348827319 0.4406364460615779" />
            </geometry>
            <material name="Cyan">
                <color rgba="0 1.0 1.0 1.0"/>
            </material>
        </visual>
        <collision>
            <origin xyz="-0.354198768829377 0.0 0.0" rpy="0 0 0"/>
            <geometry>
                <box size="0.708397537658754 0.7898101348827319 0.4406364460615779" />
            </geometry>
        </collision>
    </link>
</robot>