<robot name = "robot">
    <link name="spine0">
        <inertial>
            <origin xyz="0 0 1" rpy="0 0 0"/>
            <mass value="1" />
            <inertia ixx="100" ixy="0" ixz="0" iyy="100" iyz="0" izz="100" />
        </inertial>
        <visual>
            <origin xyz="0 0 1" rpy="0 0 0"/>
            <geometry>
                <box size="0.4837149269551585 0.6646689732648655 0.3" />
            </geometry>
            <material name="Cyan">
                <color rgba="0 1.0 1.0 1.0"/>
            </material>
        </visual>
        <collision>
            <origin xyz="0 0 1" rpy="0 0 0"/>
            <geometry>
                <box size="0.4837149269551585 0.6646689732648655 0.3" />
            </geometry>
        </collision>
    </link>
    <joint name="spine0_arm0" type="revolute">
       <parent link="spine0"/>
       <child  link="arm0"/>
       <origin rpy="0 0 0" xyz="0.0 -0.33233448663243276 1.0" />
     <axis xyz="0 1 0"/>
       <limit effort="0.0" lower="-3.14159" upper="3.14159" velocity="0.0"/>
    </joint>
    <link name="arm0">
        <inertial>
            <origin xyz="0.0 -0.09970034598972982 0.0" rpy="0 0 0"/>
            <mass value="1" />
            <inertia ixx="100" ixy="0" ixz="0" iyy="100" iyz="0" izz="100" />
        </inertial>
        <visual>
            <origin xyz="0.0 -0.09970034598972982 0.0" rpy="0 0 0"/>
            <geometry>
                <box size="0.2710461974218375 0.19940069197945964 0.2729070218500158" />
            </geometry>
            <material name="Cyan">
                <color rgba="0 1.0 1.0 1.0"/>
            </material>
        </visual>
        <collision>
            <origin xyz="0.0 -0.09970034598972982 0.0" rpy="0 0 0"/>
            <geometry>
                <box size="0.2710461974218375 0.19940069197945964 0.2729070218500158" />
            </geometry>
        </collision>
    </link>
    <joint name="spine0_arm1" type="revolute">
       <parent link="spine0"/>
       <child  link="arm1"/>
       <origin rpy="0 0 0" xyz="0.0 0.33233448663243276 1.0" />
     <axis xyz="0 1 0"/>
       <limit effort="0.0" lower="-3.14159" upper="3.14159" velocity="0.0"/>
    </joint>
    <link name="arm1">
        <inertial>
            <origin xyz="0.0 0.1183391493761907 0.0" rpy="0 0 0"/>
            <mass value="1" />
            <inertia ixx="100" ixy="0" ixz="0" iyy="100" iyz="0" izz="100" />
        </inertial>
        <visual>
            <origin xyz="0.0 0.1183391493761907 0.0" rpy="0 0 0"/>
            <geometry>
                <box size="0.4199003193930148 0.2366782987523814 0.23402104519881903" />
            </geometry>
            <material name="Cyan">
                <color rgba="0 1.0 1.0 1.0"/>
            </material>
        </visual>
        <collision>
            <origin xyz="0.0 0.1183391493761907 0.0" rpy="0 0 0"/>
            <geometry>
                <box size="0.4199003193930148 0.2366782987523814 0.23402104519881903" />
            </geometry>
        </collision>
    </link>
    <joint name="spine0_spine1" type="revolute">
       <parent link="spine0"/>
       <child  link="spine1"/>
       <origin rpy="0 0 0" xyz="-0.24185746347757925 0.0 1.0" />
     <axis xyz="0 1 0"/>
       <limit effort="0.0" lower="-3.14159" upper="3.14159" velocity="0.0"/>
    </joint>
    <link name="spine1">
        <inertial>
            <origin xyz="-0.21526602624286933 0.0 0.0" rpy="0 0 0"/>
            <mass value="1" />
            <inertia ixx="100" ixy="0" ixz="0" iyy="100" iyz="0" izz="100" />
        </inertial>
        <visual>
            <origin xyz="-0.21526602624286933 0.0 0.0" rpy="0 0 0"/>
            <geometry>
                <box size="0.43053205248573867 0.8990496893714793 0.3" />
            </geometry>
            <material name="Cyan">
                <color rgba="0 1.0 1.0 1.0"/>
            </material>
        </visual>
        <collision>
            <origin xyz="-0.21526602624286933 0.0 0.0" rpy="0 0 0"/>
            <geometry>
                <box size="0.43053205248573867 0.8990496893714793 0.3" />
            </geometry>
        </collision>
    </link>
    <joint name="arm0_leg1" type="revolute">
       <parent link="arm0"/>
       <child  link="leg1"/>
       <origin rpy="0 0 0" xyz="0.0 -0.19940069197945964 0.0" />
     <axis xyz="0 1 0"/>
       <limit effort="0.0" lower="-3.14159" upper="3.14159" velocity="0.0"/>
    </joint>
    <link name="leg1">
        <inertial>
            <origin xyz="0.0 0.0 -0.29121338843302635" rpy="0 0 0"/>
            <mass value="1" />
            <inertia ixx="100" ixy="0" ixz="0" iyy="100" iyz="0" izz="100" />
        </inertial>
        <visual>
            <origin xyz="0.0 0.0 -0.29121338843302635" rpy="0 0 0"/>
            <geometry>
                <box size="0.2667087095578455 0.14955051898459473 0.5824267768660527" />
            </geometry>
            <material name="Cyan">
                <color rgba="0 1.0 1.0 1.0"/>
            </material>
        </visual>
        <collision>
            <origin xyz="0.0 0.0 -0.29121338843302635" rpy="0 0 0"/>
            <geometry>
                <box size="0.2667087095578455 0.14955051898459473 0.5824267768660527" />
            </geometry>
        </collision>
    </link>
    <joint name="arm1_leg2" type="revolute">
       <parent link="arm1"/>
       <child  link="leg2"/>
       <origin rpy="0 0 0" xyz="0.0 0.2366782987523814 0.0" />
     <axis xyz="0 1 0"/>
       <limit effort="0.0" lower="-3.14159" upper="3.14159" velocity="0.0"/>
    </joint>
    <link name="leg2">
        <inertial>
            <origin xyz="0.0 0.0 0.05" rpy="0 0 0"/>
            <mass value="1" />
            <inertia ixx="100" ixy="0" ixz="0" iyy="100" iyz="0" izz="100" />
        </inertial>
        <visual>
            <origin xyz="0.0 0.0 0.05" rpy="0 0 0"/>
            <geometry>
                <box size="0.3149252395447611 0.17750872406428603 0.1" />
            </geometry>
            <material name="Cyan">
                <color rgba="0 1.0 1.0 1.0"/>
            </material>
        </visual>
        <collision>
            <origin xyz="0.0 0.0 0.05" rpy="0 0 0"/>
            <geometry>
                <box size="0.3149252395447611 0.17750872406428603 0.1" />
            </geometry>
        </collision>
    </link>
</robot>