<robot name = "robot">
    <link name="spine0">
        <inertial>
            <origin xyz="0 0 1" rpy="0 0 0"/>
            <mass value="1" />
            <inertia ixx="100" ixy="0" ixz="0" iyy="100" iyz="0" izz="100" />
        </inertial>
        <visual>
            <origin xyz="0 0 1" rpy="0 0 0"/>
            <geometry>
                <box size="0.3153282828496399 0.3 0.8348882018003195" />
            </geometry>
            <material name="Cyan">
                <color rgba="0 1.0 1.0 1.0"/>
            </material>
        </visual>
        <collision>
            <origin xyz="0 0 1" rpy="0 0 0"/>
            <geometry>
                <box size="0.3153282828496399 0.3 0.8348882018003195" />
            </geometry>
        </collision>
    </link>
    <joint name="spine0_arm0" type="revolute">
       <parent link="spine0"/>
       <child  link="arm0"/>
       <origin rpy="0 0 0" xyz="0.0 -0.15 1.0" />
     <axis xyz="0 1 0"/>
       <limit effort="0.0" lower="-3.14159" upper="3.14159" velocity="0.0"/>
    </joint>
    <link name="arm0">
        <inertial>
            <origin xyz="0.0 -0.045 0.0" rpy="0 0 0"/>
            <mass value="1" />
            <inertia ixx="100" ixy="0" ixz="0" iyy="100" iyz="0" izz="100" />
        </inertial>
        <visual>
            <origin xyz="0.0 -0.045 0.0" rpy="0 0 0"/>
            <geometry>
                <box size="0.12505506404521646 0.09 0.25046646054009586" />
            </geometry>
            <material name="Cyan">
                <color rgba="0 1.0 1.0 1.0"/>
            </material>
        </visual>
        <collision>
            <origin xyz="0.0 -0.045 0.0" rpy="0 0 0"/>
            <geometry>
                <box size="0.12505506404521646 0.09 0.25046646054009586" />
            </geometry>
        </collision>
    </link>
    <joint name="arm0_leg0" type="revolute">
       <parent link="arm0"/>
       <child  link="leg0"/>
       <origin rpy="0 0 0" xyz="0.0 -0.09 0.0" />
     <axis xyz="0 1 0"/>
       <limit effort="0.0" lower="-3.14159" upper="3.14159" velocity="0.0"/>
    </joint>
    <link name="leg0">
        <inertial>
            <origin xyz="0.0 0.0 -0.36538655381415397" rpy="0 0 0"/>
            <mass value="1" />
            <inertia ixx="100" ixy="0" ixz="0" iyy="100" iyz="0" izz="100" />
        </inertial>
        <visual>
            <origin xyz="0.0 0.0 -0.36538655381415397" rpy="0 0 0"/>
            <geometry>
                <box size="0.09379129803391234 0.0675 0.7307731076283079" />
            </geometry>
            <material name="Cyan">
                <color rgba="0 1.0 1.0 1.0"/>
            </material>
        </visual>
        <collision>
            <origin xyz="0.0 0.0 -0.36538655381415397" rpy="0 0 0"/>
            <geometry>
                <box size="0.09379129803391234 0.0675 0.7307731076283079" />
            </geometry>
        </collision>
    </link>
    <joint name="spine0_arm1" type="revolute">
       <parent link="spine0"/>
       <child  link="arm1"/>
       <origin rpy="0 0 0" xyz="0.0 0.15 1.0" />
     <axis xyz="0 1 0"/>
       <limit effort="0.0" lower="-3.14159" upper="3.14159" velocity="0.0"/>
    </joint>
    <link name="arm1">
        <inertial>
            <origin xyz="0.0 0.057005884403596024 0.0" rpy="0 0 0"/>
            <mass value="1" />
            <inertia ixx="100" ixy="0" ixz="0" iyy="100" iyz="0" izz="100" />
        </inertial>
        <visual>
            <origin xyz="0.0 0.057005884403596024 0.0" rpy="0 0 0"/>
            <geometry>
                <box size="0.14922046855552654 0.11401176880719205 0.29599535524495163" />
            </geometry>
            <material name="Cyan">
                <color rgba="0 1.0 1.0 1.0"/>
            </material>
        </visual>
        <collision>
            <origin xyz="0.0 0.057005884403596024 0.0" rpy="0 0 0"/>
            <geometry>
                <box size="0.14922046855552654 0.11401176880719205 0.29599535524495163" />
            </geometry>
        </collision>
    </link>
</robot>