<robot name = "robot">
    <link name="spine0">
        <inertial>
            <origin xyz="0 0 1" rpy="0 0 0"/>
            <mass value="1" />
            <inertia ixx="100" ixy="0" ixz="0" iyy="100" iyz="0" izz="100" />
        </inertial>
        <visual>
            <origin xyz="0 0 1" rpy="0 0 0"/>
            <geometry>
                <box size="0.3 0.3 0.3" />
            </geometry>
            <material name="Cyan">
                <color rgba="0 1.0 1.0 1.0"/>
            </material>
        </visual>
        <collision>
            <origin xyz="0 0 1" rpy="0 0 0"/>
            <geometry>
                <box size="0.3 0.3 0.3" />
            </geometry>
        </collision>
    </link>
    <joint name="spine0_arm0" type="revolute">
       <parent link="spine0"/>
       <child  link="arm0"/>
       <origin rpy="0 0 0" xyz="0.0 -0.15 1.0" />
     <axis xyz="0 1 0"/>
       <limit effort="0.0" lower="-3.14159" upper="3.14159" velocity="0.0"/>
    </joint>
    <link name="arm0">
        <inertial>
            <origin xyz="0.0 -0.045 0.0" rpy="0 0 0"/>
            <mass value="1" />
            <inertia ixx="100" ixy="0" ixz="0" iyy="100" iyz="0" izz="100" />
        </inertial>
        <visual>
            <origin xyz="0.0 -0.045 0.0" rpy="0 0 0"/>
            <geometry>
                <box size="0.10938598990904574 0.09 0.12281818763705298" />
            </geometry>
            <material name="Cyan">
                <color rgba="0 1.0 1.0 1.0"/>
            </material>
        </visual>
        <collision>
            <origin xyz="0.0 -0.045 0.0" rpy="0 0 0"/>
            <geometry>
                <box size="0.10938598990904574 0.09 0.12281818763705298" />
            </geometry>
        </collision>
    </link>
    <joint name="spine0_arm1" type="revolute">
       <parent link="spine0"/>
       <child  link="arm1"/>
       <origin rpy="0 0 0" xyz="0.0 0.15 1.0" />
     <axis xyz="0 1 0"/>
       <limit effort="0.0" lower="-3.14159" upper="3.14159" velocity="0.0"/>
    </joint>
    <link name="arm1">
        <inertial>
            <origin xyz="0.0 0.11539757063325048 0.0" rpy="0 0 0"/>
            <mass value="1" />
            <inertia ixx="100" ixy="0" ixz="0" iyy="100" iyz="0" izz="100" />
        </inertial>
        <visual>
            <origin xyz="0.0 0.11539757063325048 0.0" rpy="0 0 0"/>
            <geometry>
                <box size="0.09 0.23079514126650097 0.2986158885528978" />
            </geometry>
            <material name="Cyan">
                <color rgba="0 1.0 1.0 1.0"/>
            </material>
        </visual>
        <collision>
            <origin xyz="0.0 0.11539757063325048 0.0" rpy="0 0 0"/>
            <geometry>
                <box size="0.09 0.23079514126650097 0.2986158885528978" />
            </geometry>
        </collision>
    </link>
    <joint name="arm1_leg0" type="revolute">
       <parent link="arm1"/>
       <child  link="leg0"/>
       <origin rpy="0 0 0" xyz="0.0 0.23079514126650097 0.0" />
     <axis xyz="0 1 0"/>
       <limit effort="0.0" lower="-3.14159" upper="3.14159" velocity="0.0"/>
    </joint>
    <link name="leg0">
        <inertial>
            <origin xyz="0.0 0.0 -0.43646790699339005" rpy="0 0 0"/>
            <mass value="1" />
            <inertia ixx="100" ixy="0" ixz="0" iyy="100" iyz="0" izz="100" />
        </inertial>
        <visual>
            <origin xyz="0.0 0.0 -0.43646790699339005" rpy="0 0 0"/>
            <geometry>
                <box size="0.0675 0.189259334910678 0.8729358139867801" />
            </geometry>
            <material name="Cyan">
                <color rgba="0 1.0 1.0 1.0"/>
            </material>
        </visual>
        <collision>
            <origin xyz="0.0 0.0 -0.43646790699339005" rpy="0 0 0"/>
            <geometry>
                <box size="0.0675 0.189259334910678 0.8729358139867801" />
            </geometry>
        </collision>
    </link>
    <joint name="spine0_spine1" type="revolute">
       <parent link="spine0"/>
       <child  link="spine1"/>
       <origin rpy="0 0 0" xyz="-0.15 0.0 1.0" />
     <axis xyz="0 1 0"/>
       <limit effort="0.0" lower="-3.14159" upper="3.14159" velocity="0.0"/>
    </joint>
    <link name="spine1">
        <inertial>
            <origin xyz="-0.4975333077441328 0.0 0.0" rpy="0 0 0"/>
            <mass value="1" />
            <inertia ixx="100" ixy="0" ixz="0" iyy="100" iyz="0" izz="100" />
        </inertial>
        <visual>
            <origin xyz="-0.4975333077441328 0.0 0.0" rpy="0 0 0"/>
            <geometry>
                <box size="0.9950666154882656 0.7220749404199511 0.3" />
            </geometry>
            <material name="Cyan">
                <color rgba="0 1.0 1.0 1.0"/>
            </material>
        </visual>
        <collision>
            <origin xyz="-0.4975333077441328 0.0 0.0" rpy="0 0 0"/>
            <geometry>
                <box size="0.9950666154882656 0.7220749404199511 0.3" />
            </geometry>
        </collision>
    </link>
    <joint name="spine1_arm2" type="revolute">
       <parent link="spine1"/>
       <child  link="arm2"/>
       <origin rpy="0 0 0" xyz="-0.4975333077441328 -0.36103747020997556 0.0" />
     <axis xyz="0 1 0"/>
       <limit effort="0.0" lower="-3.14159" upper="3.14159" velocity="0.0"/>
    </joint>
    <link name="arm2">
        <inertial>
            <origin xyz="0.0 -0.36068981560505925 0.0" rpy="0 0 0"/>
            <mass value="1" />
            <inertia ixx="100" ixy="0" ixz="0" iyy="100" iyz="0" izz="100" />
        </inertial>
        <visual>
            <origin xyz="0.0 -0.36068981560505925 0.0" rpy="0 0 0"/>
            <geometry>
                <box size="0.7744168216726258 0.7213796312101185 0.09" />
            </geometry>
            <material name="Cyan">
                <color rgba="0 1.0 1.0 1.0"/>
            </material>
        </visual>
        <collision>
            <origin xyz="0.0 -0.36068981560505925 0.0" rpy="0 0 0"/>
            <geometry>
                <box size="0.7744168216726258 0.7213796312101185 0.09" />
            </geometry>
        </collision>
    </link>
</robot>