<robot name = "robot">
    <link name="spine0">
        <inertial>
            <origin xyz="0 0 1" rpy="0 0 0"/>
            <mass value="1" />
            <inertia ixx="100" ixy="0" ixz="0" iyy="100" iyz="0" izz="100" />
        </inertial>
        <visual>
            <origin xyz="0 0 1" rpy="0 0 0"/>
            <geometry>
                <box size="0.3 0.9851797853845499 0.33556065193672" />
            </geometry>
            <material name="Cyan">
                <color rgba="0 1.0 1.0 1.0"/>
            </material>
        </visual>
        <collision>
            <origin xyz="0 0 1" rpy="0 0 0"/>
            <geometry>
                <box size="0.3 0.9851797853845499 0.33556065193672" />
            </geometry>
        </collision>
    </link>
    <joint name="spine0_spine1" type="revolute">
       <parent link="spine0"/>
       <child  link="spine1"/>
       <origin rpy="0 0 0" xyz="-0.15 0.0 1.0" />
     <axis xyz="0 1 0"/>
       <limit effort="0.0" lower="-3.14159" upper="3.14159" velocity="0.0"/>
    </joint>
    <link name="spine1">
        <inertial>
            <origin xyz="-0.4556843576891903 0.0 0.0" rpy="0 0 0"/>
            <mass value="1" />
            <inertia ixx="100" ixy="0" ixz="0" iyy="100" iyz="0" izz="100" />
        </inertial>
        <visual>
            <origin xyz="-0.4556843576891903 0.0 0.0" rpy="0 0 0"/>
            <geometry>
                <box size="0.9113687153783806 0.43840589213191317 0.6635434138590129" />
            </geometry>
            <material name="Cyan">
                <color rgba="0 1.0 1.0 1.0"/>
            </material>
        </visual>
        <collision>
            <origin xyz="-0.4556843576891903 0.0 0.0" rpy="0 0 0"/>
            <geometry>
                <box size="0.9113687153783806 0.43840589213191317 0.6635434138590129" />
            </geometry>
        </collision>
    </link>
    <joint name="spine1_arm0" type="revolute">
       <parent link="spine1"/>
       <child  link="arm0"/>
       <origin rpy="0 0 0" xyz="-0.4556843576891903 -0.21920294606595658 0.0" />
     <axis xyz="0 1 0"/>
       <limit effort="0.0" lower="-3.14159" upper="3.14159" velocity="0.0"/>
    </joint>
    <link name="arm0">
        <inertial>
            <origin xyz="0.0 -0.06576088381978697 0.0" rpy="0 0 0"/>
            <mass value="1" />
            <inertia ixx="100" ixy="0" ixz="0" iyy="100" iyz="0" izz="100" />
        </inertial>
        <visual>
            <origin xyz="0.0 -0.06576088381978697 0.0" rpy="0 0 0"/>
            <geometry>
                <box size="0.7530397793708983 0.13152176763957393 0.19906302415770388" />
            </geometry>
            <material name="Cyan">
                <color rgba="0 1.0 1.0 1.0"/>
            </material>
        </visual>
        <collision>
            <origin xyz="0.0 -0.06576088381978697 0.0" rpy="0 0 0"/>
            <geometry>
                <box size="0.7530397793708983 0.13152176763957393 0.19906302415770388" />
            </geometry>
        </collision>
    </link>
    <joint name="spine1_arm1" type="revolute">
       <parent link="spine1"/>
       <child  link="arm1"/>
       <origin rpy="0 0 0" xyz="-0.4556843576891903 0.21920294606595658 0.0" />
     <axis xyz="0 1 0"/>
       <limit effort="0.0" lower="-3.14159" upper="3.14159" velocity="0.0"/>
    </joint>
    <link name="arm1">
        <inertial>
            <origin xyz="0.0 0.15922223612615521 0.0" rpy="0 0 0"/>
            <mass value="1" />
            <inertia ixx="100" ixy="0" ixz="0" iyy="100" iyz="0" izz="100" />
        </inertial>
        <visual>
            <origin xyz="0.0 0.15922223612615521 0.0" rpy="0 0 0"/>
            <geometry>
                <box size="0.40093039296111416 0.31844447225231043 0.19906302415770388" />
            </geometry>
            <material name="Cyan">
                <color rgba="0 1.0 1.0 1.0"/>
            </material>
        </visual>
        <collision>
            <origin xyz="0.0 0.15922223612615521 0.0" rpy="0 0 0"/>
            <geometry>
                <box size="0.40093039296111416 0.31844447225231043 0.19906302415770388" />
            </geometry>
        </collision>
    </link>
</robot>