<robot name = "robot">
    <link name="spine0">
        <inertial>
            <origin xyz="0 0 1" rpy="0 0 0"/>
            <mass value="1" />
            <inertia ixx="100" ixy="0" ixz="0" iyy="100" iyz="0" izz="100" />
        </inertial>
        <visual>
            <origin xyz="0 0 1" rpy="0 0 0"/>
            <geometry>
                <box size="0.5807564011745618 0.7461726824661743 0.3" />
            </geometry>
            <material name="Cyan">
                <color rgba="0 1.0 1.0 1.0"/>
            </material>
        </visual>
        <collision>
            <origin xyz="0 0 1" rpy="0 0 0"/>
            <geometry>
                <box size="0.5807564011745618 0.7461726824661743 0.3" />
            </geometry>
        </collision>
    </link>
    <joint name="spine0_arm0" type="revolute">
       <parent link="spine0"/>
       <child  link="arm0"/>
       <origin rpy="0 0 0" xyz="0.0 -0.37308634123308715 1.0" />
     <axis xyz="0 1 0"/>
       <limit effort="0.0" lower="-3.14159" upper="3.14159" velocity="0.0"/>
    </joint>
    <link name="arm0">
        <inertial>
            <origin xyz="0.0 -0.11192590236992614 0.0" rpy="0 0 0"/>
            <mass value="1" />
            <inertia ixx="100" ixy="0" ixz="0" iyy="100" iyz="0" izz="100" />
        </inertial>
        <visual>
            <origin xyz="0.0 -0.11192590236992614 0.0" rpy="0 0 0"/>
            <geometry>
                <box size="0.4119534038445426 0.22385180473985228 0.22031897376409662" />
            </geometry>
            <material name="Cyan">
                <color rgba="0 1.0 1.0 1.0"/>
            </material>
        </visual>
        <collision>
            <origin xyz="0.0 -0.11192590236992614 0.0" rpy="0 0 0"/>
            <geometry>
                <box size="0.4119534038445426 0.22385180473985228 0.22031897376409662" />
            </geometry>
        </collision>
    </link>
    <joint name="arm0_leg0" type="revolute">
       <parent link="arm0"/>
       <child  link="leg0"/>
       <origin rpy="0 0 0" xyz="0.0 -0.22385180473985228 0.0" />
     <axis xyz="0 1 0"/>
       <limit effort="0.0" lower="-3.14159" upper="3.14159" velocity="0.0"/>
    </joint>
    <link name="leg0">
        <inertial>
            <origin xyz="0.0 0.0 -0.46543372246175657" rpy="0 0 0"/>
            <mass value="1" />
            <inertia ixx="100" ixy="0" ixz="0" iyy="100" iyz="0" izz="100" />
        </inertial>
        <visual>
            <origin xyz="0.0 0.0 -0.46543372246175657" rpy="0 0 0"/>
            <geometry>
                <box size="0.3089650528834069 0.215453432228855 0.9308674449235131" />
            </geometry>
            <material name="Cyan">
                <color rgba="0 1.0 1.0 1.0"/>
            </material>
        </visual>
        <collision>
            <origin xyz="0.0 0.0 -0.46543372246175657" rpy="0 0 0"/>
            <geometry>
                <box size="0.3089650528834069 0.215453432228855 0.9308674449235131" />
            </geometry>
        </collision>
    </link>
    <joint name="spine0_spine1" type="revolute">
       <parent link="spine0"/>
       <child  link="spine1"/>
       <origin rpy="0 0 0" xyz="-0.2903782005872809 0.0 1.0" />
     <axis xyz="0 1 0"/>
       <limit effort="0.0" lower="-3.14159" upper="3.14159" velocity="0.0"/>
    </joint>
    <link name="spine1">
        <inertial>
            <origin xyz="-0.27838794138860123 0.0 0.0" rpy="0 0 0"/>
            <mass value="1" />
            <inertia ixx="100" ixy="0" ixz="0" iyy="100" iyz="0" izz="100" />
        </inertial>
        <visual>
            <origin xyz="-0.27838794138860123 0.0 0.0" rpy="0 0 0"/>
            <geometry>
                <box size="0.5567758827772025 0.3 0.8266597244893367" />
            </geometry>
            <material name="Cyan">
                <color rgba="0 1.0 1.0 1.0"/>
            </material>
        </visual>
        <collision>
            <origin xyz="-0.27838794138860123 0.0 0.0" rpy="0 0 0"/>
            <geometry>
                <box size="0.5567758827772025 0.3 0.8266597244893367" />
            </geometry>
        </collision>
    </link>
</robot>